I'm sorry, but an uncaught exception occurred.

While running game code:
  File "game/script.rpy", line 15, in script
    $ all_saves.data["health"] += 50
  File "game/script.rpy", line 15, in <module>
    $ all_saves.data["health"] += 50
KeyError: 'health'

-- Full Traceback ------------------------------------------------------------

Full traceback:
  File "game/script.rpy", line 15, in script
    $ all_saves.data["health"] += 50
  File "C:\Program Files\renpy-8.2.1-sdk\renpy\ast.py", line 823, in execute
    renpy.python.py_exec_bytecode(self.code.bytecode, self.hide, store=self.store)
  File "C:\Program Files\renpy-8.2.1-sdk\renpy\python.py", line 1178, in py_exec_bytecode
    exec(bytecode, globals, locals)
  File "game/script.rpy", line 15, in <module>
    $ all_saves.data["health"] += 50
KeyError: 'health'

Windows-10-10.0.19045 AMD64
Ren'Py 8.2.1.24030407
Jays RNG 1.0
Wed May 22 13:47:50 2024
